Workbook

Sheet Julio - R&D Tracker
A1: CDLS PLATFORM - R&D TAX CREDIT TIME TRACKER
A2: Employee: Julio Umanzor | Role: Founder/Managing Partner (R&D Focus)
A3: CRITICAL: Must be completed CONTEMPORANEOUSLY (same day as work performed)
A5: Date | B5: Project Code | C5: Project Name | D5: Activity Description | E5: Hours | F5: Four-Part Test Met? | G5: Technical Uncertainty | H5: Experimentation Method | I5: Supervisor Approval
A6: 2025-10-15 | B6: AI-001 | C6: AI Route Optimization — ML Model Selection & Validation | D6: Literature review of ML routing methods (1.0h) · Dataset preparation and cleaning (1.5h) · Implementation of 3 model variants: linear, polynomial, neural network (2.0h) · A/B comparative testing and accuracy benchmarking (2.0h) | E6: 6.5 | F6: YES | G6: Uncertain which ML model would achieve <10% error rate for route prediction across variable traffic conditions | H6: A/B testing: compared 3 models using historical traffic data; measured prediction accuracy and computation time | I6: Self (Founder)
A7: 2025-10-16 | B7: BLOCKCHAIN-001 | C7: Carbon Credit Automation — Smart Contract Architecture & CARB API Integration | D7: CARB LCFS regulation review (1.0h) · Smart contract schema design (2.0h) · API endpoint prototype coding (2.0h) · Rate-limit stress testing and latency measurement (2.0h) | E7: 7 | F7: YES | G7: Unknown whether CARB legacy systems could interface with blockchain via API calls without manual intervention | H7: Iterative testing: built 3 prototype contracts, tested API integration, refined based on CARB response times | I7: Self (Founder)
A8: 2025-10-17 | B8: FLEET-001 | C8: Fleet Management Dashboard — Tesla Semi Telemetry & Predictive Maintenance | D8: Tesla API exploration and integration (2.0h) · Degradation dataset collection and preprocessing (2.0h) · Regression model for battery health prediction (2.5h) · Dashboard UI prototype (1.5h) | E8: 8 | F8: YES | G8: Battery degradation prediction accuracy for Tesla Semi under 9-vehicle hauling loads not established in industry literature | H8: Statistical modeling: collected Semi beta fleet data, applied regression analysis, validated predictions vs actual degradation | I8: Self (Founder)
A9: 2025-10-18 | B9: COMPLIANCE-001 | C9: JUDAS AI Integrity Kernel — Zero-Knowledge Proof Architecture Design | D9: ZKP scheme comparative research — zk-SNARKs vs Pedersen vs dual-SHA-256 (2.5h) · Cryptographic commitment schema drafting (2.0h) · PoC hash pipeline coding (2.0h) · Collision probability & latency benchmarking on 20 synthetic freight images (1.0h) | E9: 7.5 | F9: YES | G9: Uncertain whether dual-hash commitment scheme could provide court-admissible non-repudiation for freight disputes without full image disclosure, and whether SHA-256 collision resistance satisfied GAGAS audit standards. | H9: Comparative protocol review of 3 ZKP schemes; PoC hash pipeline benchmarked against 20 synthetic freight images for collision probability and latency. | I9: Self (Founder)
A10: 2025-10-19 | B10: COMPLIANCE-001 | C10: JUDAS AI — Computer Vision Damage Detection Model Prototype | D10: Pre-trained model evaluation: YOLO v8 vs ResNet-50 (2.0h) · Bounding-box annotation pipeline (2.0h) · OpenCV preprocessing integration (1.0h) · Precision/recall benchmarking at 0.5 IoU under 3 lighting conditions (3.0h) | E10: 8 | F10: YES | G10: Uncertain whether pre-trained COCO weights would transfer to automotive freight damage detection with <5% false-negative rate under variable lot lighting (dawn, dusk, overcast), or whether domain-specific fine-tuning was required. | H10: A/B model comparison: YOLO v8 vs. ResNet-50 fine-tuned on 500 synthetic damage images; precision/recall at 0.5 IoU under 3 simulated lighting conditions. | I10: Self (Founder)
A11: 2025-10-20 | B11: DEALER-001 | C11: Dealer Dashboard & ACF Compliance Reporting — CARB API Automation Prototype | D11: CARB reporting schema analysis (1.0h) · Dashboard wireframe and build (2.0h) · API integration prototype (1.5h) · 3-iteration testing and refinement with pilot dealer (1.0h) | E11: 5.5 | F11: YES | G11: Automation of ACF quarterly reports to meet CARB deadlines without human intervention was technically uncertain | H11: Prototype testing: 3 iterations, tested with sample data, refined automation logic, beta tested with pilot dealer | I11: Self (Founder)
A12: 2025-12-10 | B12: FLEET-001 | C12: MagSafe Quick-Disconnect Battery Pod System — Mechanical & Electrical Design | D12: Magnetic coupling force analysis and material selection — N52 NdFeB vs electromagnet vs hybrid (2.5h) · Spring-loaded cable retraction spec (2.0h) · Arc-fault detection interlock modeling (2.0h) · Thermal cycling material evaluation −10°F to 115°F (2.5h) | E12: 9 | F12: YES | G12: Uncertain whether magnetic coupling force sufficient for road-vibration retention could be achieved without exceeding foot-pedal release ergonomic limits (<25 lb), and whether spring-loaded retraction could survive 3,000+ daily cycles without cable jacket fatigue. | H12: Iterative CAD force simulation: 3 magnet array configurations tested against pull-force and ergonomics targets; fatigue cycle modeling on cable jacket cross-sections. | I12: Self (Founder)
A13: 2025-12-15 | B13: FLEET-001 | C13: MagSafe Quick-Disconnect — USPTO Provisional Patent #63/734829 Drafting | D13: Prior-art search: 400+ patents across IPC H01R, B60L, H02J (4.0h) · Independent claims drafting — 3 scope iterations (3.5h) · Technical drawing preparation (2.0h) · Enablement specification authoring (1.5h) | E13: 11 | F13: YES | G13: Uncertain whether claim scope covering both permanent-magnet and electromagnet embodiments would survive prior-art rejection given Tesla supercharger coupling patents, and whether the misalignment-tolerance claim was novel vs. existing industrial connector standards. | H13: Prior-art search across 400+ patents; 3 iterative claim scope revisions to balance breadth vs. patentability. | I13: Self (Founder)
A14: 2026-01-20 | B14: AI-001 | C14: Rule 42.1 Dynamic Payload Range Engine — Temperature/Load Derating Model | D14: LFP cell thermal characteristics literature review (4.0h) · Derating equation formulation and parameterization (8.0h) · Regression model coding for degradation tracking under hauling loads (12.0h) · 38°F winter derating validation (8.0h) · Iterative refinement (8.0h) | E14: 40 | F14: YES | G14: Uncertain how external temperature and heavy payload loads dynamically degrade range in real-time dispatch | H14: Iterative mathematical modeling against ambient parameters (38°F winter derating); regression tracking against actual fleet data | I14: Self (Founder)
A15: 2026-01-21 | B15: COMPLIANCE-001 | C15: CARB CTC & TRUCRS Automated API Handshake — VIN/Serial Cross-Query Engine | D15: CARB API endpoint mapping (3.0h) · VIN parsing and validation pipeline (4.0h) · High-volume query prototype (5.0h) · Transaction-limit stress testing and fallback logic (6.0h) · Latency validation against simulated endpoints (4.5h) | E15: 22.5 | F15: YES | G15: Uncertain if existing API endpoints could reliably process high-volume serial queries without transaction limits blocking route clearances | H15: Prototype integration and latency testing against simulated CARB database endpoints; fallback logic stress-tested | I15: Self (Founder)
A16: 2026-01-22 | B16: DEALER-001 | C16: Tier 1 DEK Credential Isolation Store — Multi-Tenant Encryption Architecture | D16: Threat modeling and key-rotation schema design (5.0h) · DEK isolation model implementation (8.0h) · Fallback gating logic (5.0h) · Encryption overhead simulation and systematic unit testing (10.0h) | E16: 28 | F16: YES | G16: Design uncertainty regarding cryptographic key rotation vs database latency requirements in a multi-tenant environment | H16: Simulation of encryption overhead on query execution time and systematic unit testing | I16: Self (Founder)
A17: 2026-01-23 | B17: FLEET-001 | C17: Portable Battery Pod Trailer — 360 kWh Electrical System Architecture | D17: EcoFlow DELTA Pro Ultra stack configuration analysis (2.0h) · DC bus and 400V pack voltage specification (2.0h) · BMS integration design — cell balancing, thermal mgmt (2.0h) · Bidirectional inverter spec 38.4 kW V2G (1.5h) · LFP DoD degradation curve modeling 80% vs 90% (1.0h) | E17: 8.5 | F17: YES | G17: Uncertain whether LFP cells in a 120-unit parallel string could achieve balanced state-of-charge during high-rate V2G discharge (38.4 kW for 5.8 hrs), and whether 80% DoD was sufficient to meet SMUD ELRP requirements while preserving 3,000-cycle lifespan. | H17: Electrochemical modeling: 3,000-cycle degradation at 80% vs. 90% DoD using EcoFlow cell data; cell-balancing algorithm validated on 10-unit prototype. | I17: Self (Founder)
... A36: 2026-08-22 | B36: COMPLIANCE-001 | C36: OCR Preprocessing & PII Escalation — Tesseract/PIL Pipeline & Confidence Threshold Routing | D36: Tesseract integration and DPI parameterization: 200 vs 300 DPI (4.0h) · PIL binarization preprocessing pipeline (3.0h) · 0.7 confidence threshold routing logic and NumPy 2.x conflict resolution (3.0h) · Empirical trial testing across 60+ synthetic PDFs (6.0h) | E36: 16 | F36: YES | G36: Uncertain how OCR transcription errors (punctuation drops in Federal ALN/PCA codes) affect NLP regex tokenization and redaction recall. | H36: Empirical trial testing across 60+ synthetic PDF samples under varying DPI (200 vs 300) and threshold filters to measure recall consistency. | I36: Self (Founder)
A37: 2026-08-24 | B37: DEALER-001 | C37: AAD-Bound AEAD Credential Boundary — AES-256-GCM Multi-Tenant Cryptographic Isolation | I37: Self (Founder)
A38: 2026-08-25 | B38: COMPLIANCE-001 | C38: Trace Observability & Context Propagation — Async Contextvars Trace Correlation Engine | I38: Self (Founder)
A39: 2026-08-28 | B39: COMPLIANCE-001 | C39: CARB Clean Truck Check (HD I/M) Engine — OBD/Opacity Compliance Rule Tree Under 13 CCR §§ 2195-2199 | I39: Self (Founder)
A40: 2026-09-08 | B40: FLEET-001 | C40: Sanitized Packaging & Release Gate — Git History Verification & AST Regex Secret-Leak Prevention | I40: Self (Founder)
A41: 2026-09-10 | B41: AI-001 | C41: MCMC + OLS Regression Hybrid Route Engine — 10-Year Noise Removal & Human-Centric A/B Stabilization Integration | I41: Self (Founder)
A42: 2026-09-10 | B42: AI-001 | C42: CESAR Parallel Subagent Execution Architecture — Multi-Agent Concurrent Task Orchestration Framework | I42: Self (Founder)
A43: 45306 | B43: DEALER-001 | C43: Dealer Dashboard — Phase 0: ACF Compliance Burden Analysis & Cost Baseline | I43: Self (Founder)
A44: 45313 | B44: DEALER-001 | C44: Dealer Dashboard — Phase 0: California Dealer Network TAM & Milestone Mapping | I44: Self (Founder)
A45: 45327 | B45: DEALER-001 | C45: Dealer Dashboard — Phase 0: Per-Truck P&L & Incentive Stacking Model | I45: Self (Founder)
A46: 45483 | B46: AI-001 | C46: AI Route Optimization — Phase 1: CESAR Multi-Agent Controller Architecture Design | I46: Self (Founder)
A47: 45491 | B47: AI-001 | C47: AI Route Optimization — Phase 1: Local Ollama LLM Deployment & Inference Benchmarking | I47: Self (Founder)
A48: 45506 | B48: DEALER-001 | C48: Dealer Dashboard — Phase 1: Dealer Onboarding Agent v0.1 Automated Workflow | I48: Self (Founder)
A49: 45550 | B49: AI-001 | C49: AI Route Optimization — Phase 1: CESAR Agent Coordination Stress Testing | D49: Unit + integration testing of CESAR agent coordination; failure mode analysis under simulated load | E49: 14 | F49: YES | G49: What failure modes emerge when multiple agents process concurrent dispatch requests? | H49: Stress Testing: 3 edge cases identified in agent handoff; revised coordination protocol | I49: Self (Founder)
A50: 45568 | B50: AI-001 | C50: AI Route Optimization — Phase 2: Monte Carlo Route Optimization Algorithm Development | D50: Route Optimization Agent: implemented Monte Carlo simulation for multi-depot delivery route optimization | E50: 20 | F50: YES | G50: Can MCMC simulation achieve >95% route accuracy vs optimal? Unproven for CA dealer geography | H50: Algorithm Development: 97.3% accuracy vs optimal benchmark on pilot dataset (20 dealers, 283 hauls) | I50: Self (Founder)
A51: 45585 | B51: AI-001 | C51: AI Route Optimization — Phase 2: Real-Time CAISO Pricing API Route Integration | D51: Integrated real-time CAISO pricing API into route optimizer: route decisions account for V2G peak window (4–9 PM) | E51: 14 | F51: YES | G51: Can routing dynamically defer hauls to protect V2G revenue window without throughput loss? | H51: Integration Testing: Haul deferral algorithm reduces V2G revenue conflict by 78%; throughput maintained | I51: Self (Founder)
A52: 45604 | B52: AI-001 | C52: AI Route Optimization — Phase 2: Route Optimizer Pilot A/B Controlled Trial | D52: Pilot A/B test: AI-optimized routes vs human dispatcher baseline (20-dealer cohort, 6 weeks) | E52: 18 | F52: YES | G52: Does Monte Carlo route optimization outperform human dispatcher on cost and time? | H52: A/B Experimentation: AI routes: 12.3% cost reduction, 97.3% on-time vs 84.2% human baseline | I52: Self (Founder)
A53: 45667 | B53: AI-001 | C53: AI Route Optimization — Phase 3: Financial Model v7.2 Bottom-Up Cost Rebuild | D53: Financial model v1→v7.2: iterative rebuild; variable cost derivation from scratch (replaced $45 placeholder) | E53: 40 | F53: YES | G53: Can per-truck variable costs be derived bottom-up with sufficient precision for LP disclosure? | H53: Quantitative Modeling: v7.2 frozen: 9.7% unlevered ROIC, 1.80x DSCR, $6.5M LP equity req; 5.8% volume cushion to covenant breach | I53: Self (Founder)
A54: 45702 | B54: AI-001 | C54: AI Route Optimization — Phase 3: §45W & §30C Federal Credit Termination Impact Analysis | D54: §45W and §30C credit analysis; confirmed termination under One Big Beautiful Bill Act; removed from model | E54: 6 | F54: YES | G54: Do federal credits remain available post-2025 legislation? Critical model assumption | H54: Regulatory Research: Both credits confirmed terminated 2025-26; $140K/truck federal stack removed from projections | I54: Self (Founder)
A55: 45717 | B55: AI-001 | C55: AI Route Optimization — Phase 3: Capital Stack Rebuild & EVSE Incentive Restack | D55: Capital stack rebuild: added charging infrastructure and working capital (previously omitted); full incentive restack | E55: 24 | F55: YES | G55: Does omission of EVSE capex and working capital materially affect LP disclosure accuracy? | H55: Quantitative Modeling: $21.3M total capital confirmed; ~$9.5M incentive face-value; model materially different from v1 | I55: Self (Founder)
A56: 45752 | B56: BLOCKCHAIN-001 | C56: Carbon Credit Automation — Phase 4: Three-Token Ecosystem Architecture Design | D56: Three-token ecosystem architecture: $CDLS (ERC-20 governance), $HAUL (ERC-20 utility/deflationary), $CARBON (ERC-721 NFT) | E56: 16 | F56: YES | G56: Can tokenized carbon credits achieve secondary market liquidity and Verra VCS certification? | H56: System Architecture: Token architecture defined; legal structure requires securities counsel review (Reg D path) | I56: Self (Founder)
A57: 45789 | B57: BLOCKCHAIN-001 | C57: Carbon Credit Automation — Phase 4: Automated Revenue Distribution & $CARBON Mint Smart Contract | D57: Smart contract: auto-trigger revenue distribution on haul completion; $CARBON mint on haul verification | E57: 20 | F57: YES | G57: Can smart contract automation replace manual revenue distribution with <24h settlement? | H57: Prototype Build: Smart contract functional in testnet; 23-minute average settlement (target <24h) | I57: Self (Founder)
A58: 45809 | B58: BLOCKCHAIN-001 | C58: Carbon Credit Automation — Phase 4: OpenZeppelin Contract Security Audit & Gas Optimization | D58: OpenZeppelin contract audit + gas optimization for Layer 2 deployment | E58: 18 | F58: YES | G58: Do contracts meet security standards for production deployment with real LP capital? | H58: Security Testing: 2 medium-severity issues resolved; gas reduced 34% via struct packing | I58: Self (Founder)
A59: 45846 | B59: FLEET-001 | C59: Fleet Management Dashboard — Phase 5: QIE CAISO Real-Time Price Prediction Engine | D59: QIE (Quantitative Intelligence Engine): CAISO real-time price feed → CESAR autonomous V2G dispatch decisions | E59: 24 | F59: YES | G59: Can forex arbitrage methodology (MCMC + regression) predict CAISO peak pricing with >80% accuracy? | H59: Algorithm Development: 82.3% price prediction accuracy; V2G dispatch optimization improves revenue estimate by $6,200/truck/yr | I59: Self (Founder)
...

Sheet Project Codes
A1: R&D PROJECT CODES REFERENCE
A3: Project Code | B3: Project Name | C3: Description | D3: Budget Hours (Year 1)
A4: AI-001 | B4: AI Route Optimization | C4: Machine learning algorithms for optimal haul routing | D4: 400
A5: AI-002 | B5: Load Balancing Algorithm | C5: Dynamic load distribution across fleet based on capacity/location | D5: 250
A6: BLOCKCHAIN-001 | B6: Carbon Credit Automation | C6: Smart contracts for automated LCFS credit minting | D6: 350
A7: BLOCKCHAIN-002 | B7: Token Ecosystem | C7: Development of $CDLS, $HAUL, $CARBON tokenomics | D7: 300
A8: FLEET-001 | B8: Fleet Management Dashboard | C8: Real-time tracking, predictive maintenance, battery optimization | D8: 450
A9: FLEET-002 | B9: Tesla Semi Integration | C9: API integration with Tesla telemetry and charging systems | D9: 200
A10: DEALER-001 | B10: Dealer Dashboard | C10: Automated reporting, ACF compliance, carbon credit tracking | D10: 350
A11: DEALER-002 | B11: DMS Integration | C11: Integration with CDK, Reynolds & Reynolds, Dealertrack systems | D11: 300
A12: COMPLIANCE-001 | B12: CARB Automation | C12: Automated ACF quarterly reporting to CARB | D12: 200
A13: COMPLIANCE-002 | B13: LCFS Credit Calculation | C13: Automated calculation of carbon credits per haul | D13: 150

Sheet Four-Part Test Guide
A1: R&D TAX CREDIT: FOUR-PART TEST REQUIREMENTS
A3: Test Component | B3: Requirement | C3: CDLS Examples
A4: 1. TECHNOLOGICAL IN NATURE | B4: Activity must rely on principles of computer science, engineering, physics, chemistry, biology, or similar field | C4: AI route optimization uses machine learning (computer science); Blockchain smart contracts use cryptography; Fleet management uses software engineering
A5: 2. ELIMINATE TECHNICAL UNCERTAINTY | B5: Outcome must not be known in advance. Developer faces uncertainty about capability, methodology, or appropriate design | C5: Unknown: Will ML model achieve <10% error rate? Unknown: Can CARB API support real-time blockchain integration? Unknown: Accuracy of battery degradation prediction under 9-vehicle loads
A6: 3. PROCESS OF EXPERIMENTATION | B6: Must use systematic trial-and-error, modeling, simulation, or other method to evaluate alternatives | C6: A/B testing multiple ML models; Iterative smart contract development; Statistical modeling of battery degradation; Prototype testing with pilot dealers
A7: 4. BUSINESS COMPONENT | B7: Must improve function, performance, reliability, or quality of a product, process, software, technique, formula, or invention | C7: Improved function: Faster route optimization; Improved performance: Real-time vs batch processing; Improved reliability: 99.9% uptime for tracking; Improved quality: <2% error rate in carbon calculations

Sheet Qualified vs Non-Qualified
A1: QUALIFIED vs NON-QUALIFIED R&D ACTIVITIES
A3: QUALIFIED ACTIVITIES (Include in tracker) | B3: NON-QUALIFIED ACTIVITIES (Exclude from tracker)
A4: ✓ Developing algorithms (ML, optimization, etc.) | B4: ✗ General business planning
A5: ✓ Writing code for new features/functionality | B5: ✗ Marketing & sales activities
A6: ✓ Testing and debugging complex systems | B6: ✗ Routine data entry or admin tasks
A7: ✓ Designing databases or system architecture | B7: ✗ Meeting with investors/dealers (non-technical)
A8: ✓ API integration (when methodology uncertain) | B8: ✗ Routine software maintenance
A9: ✓ Prototyping and iterative development | B9: ✗ User training or documentation
A10: ✓ Performance optimization (uncertain outcome) | B10: ✗ Legal or accounting work
A11: ✓ Statistical modeling and data analysis | B11: ✗ Fundraising activities
A12: ✓ Technical research (reading papers, testing) | B12: ✗ Hiring or HR activities
A13: ✓ Code review of experimental features | B13: ✗ Routine email and communication

Sheet Retroactive Documentation
A1: RETROACTIVE R&D DOCUMENTATION FOR PRE-INCORPORATION WORK
A2: Can Julio claim R&D credits for work done BEFORE C-Corp formation?
A4: GOOD NEWS: | B4: You CAN claim R&D credits for pre-incorporation development work!
A5: REQUIREMENTS: | B5: 1. Work must have been performed in 2026 (tax year you are claiming credit)
B6: 2. You must have documentation that you can REASONABLY RECONSTRUCT
B7: 3. C-Corp must be formed and you must be W-2 employee by year-end 2026
B8: 4. Time must be allocated to R&D activities (not general planning)
A9: WHAT TO DO NOW: | B9: Step 1: Reconstruct your 2025 work (if claiming 2025 credits, requires amended 2025 return)
B10: Step 2: Document 2026 work going forward (CONTEMPORANEOUS from today)
B11: Step 3: Gather supporting evidence: emails, GitHub commits, meeting notes, design docs
B12: Step 4: Work with CPA to allocate % of your time to qualified R&D vs general business
A13: EXAMPLE CALCULATION: | B13: Julio's 2026 Salary (W-2): $160,000
B14: Estimated R&D Time: 60% (rest is general management, fundraising, admin)
B15: Qualified Wages: $160,000 x 60% = $96,000
B16: Federal R&D Credit: $96,000 x 14% = $13,440
B17: California R&D Credit: $96,000 x 15% = $14,400
B18: TOTAL CREDIT (Julio only): $27,840
A19: CRITICAL: | B19: For 2026 credits, you must be W-2 employee (not contractor, not owner draw)
B20: ROBS plan requires you to be employee, so this aligns perfectly
B21: Set reasonable salary ($160K-$200K for founder/CTO role)
A22: DOCUMENTATION TIPS: | B22: 1. Review calendar/emails to reconstruct time spent on technical work
B23: 2. Export GitHub commits (shows code development dates)
B24: 3. Gather design documents, whitepapers, technical memos you wrote
B25: 4. Estimate hours conservatively (60% R&D is reasonable, 90% would raise red flags)
B26: 5. Get CPA to review and approve allocation before filing

Sheet Instructions & Legal Basis
A1: CDLS R&D LOG — Instructions, Legal Basis & Completion Guide
A3: PURPOSE
A4: This log supports IRC § 41 Federal Research & Experimentation Credit and California R&TC § 23609 credit claims for CDLS / California Investment Auto LP. It documents qualified research activities (QRAs) with sufficient contemporaneous detail to survive IRS examination under the Cohan rule and Reg. § 1.41-4.
A6: LEGAL STANDARD — FEDERAL
A7: IRC § 41(d) requires: (1) Permitted purpose — developing a new/improved business component; (2) Technological in nature — relies on hard science or computer science; (3) Eliminates uncertainty — capability, method, or design was uncertain at the start; (4) Process of experimentation — evaluate one or more alternatives through testing, modeling, or simulation.
A9: LEGAL STANDARD — CALIFORNIA
A10: R&TC § 23609 mirrors federal § 41 but applies a 15% credit rate to QREs exceeding the base amount. California does not conform to the TCJA capitalization requirement for § 174 — consult your CA tax counsel.
A12: HOW TO USE THIS LOG
A14: Step 1 | B14: Activity Log tab | D14: Record each R&D session within 7 days of occurrence (IRS 'contemporaneous' standard). Include: date, phase, category, specific activity description, technical uncertainty addressed, hours, and outcome.
A16: Step 2 | B16: 4-Part Test column | D16: Mark 'Yes' only if all 4 statutory elements are satisfied. When in doubt, describe why in the Notes column.
A18: Step 3 | B18: Hours | D18: Record actual hours worked. Blue cells = editable inputs. Support with calendar entries, git commits (timestamped), email threads, or draft documents from the same date.
A20: Step 4 | B20: Summary Dashboard | D20: Review Phase totals quarterly. Flag any phase where QRE % drops below 75% for counsel review.
A22: Step 5 | B22: Hour Breakdown tab | D22: Use as estimation guide when reconstructing hours. Match activity to category; apply typical percentage ranges as a reasonableness check.
A24: WHAT CDLS QUALIFIES — KEY POINTS
A26: CESAR Controller | D26: Novel multi-agent AI architecture with <2s inference target — technical uncertainty present; computer science basis; iterative testing documented.
A28: Route Optimization (MCMC) | D28: Monte Carlo simulation applied to novel dealer-geographic routing problem — algorithmic uncertainty, process of experimentation via A/B testing.
A30: V2G / QIE Integration | D30: Applying forex MCMC methodology to CAISO energy arbitrage — technically uncertain, novel application, A/B tested against baseline.
A32: Financial Model v7.2 | D32: Portions qualify: deriving variable costs bottom-up (technical uncertainty about cost structure), capital stack optimization. Business-planning portions do NOT qualify.
A34: Blockchain Token Architecture | D34: Smart contract design for novel carbon credit NFT + deflationary utility token — technical uncertainty in contract security and gas optimization.
A36: WHAT DOES NOT QUALIFY
A38: Non-QRE Items | D38: Investor pitching, LP agreement drafting, general management, dealer relationship management, accounting, marketing. These must be segregated from QRE hours. When an activity is mixed (e.g., a demo that also tests the system), allocate hours proportionally.
A40: RECORD RETENTION
A41: Retain this log and all supporting records for: Federal — 3 years from filing date (7 years if >25% income understatement risk). California — 4 years from assessment date. Store with git logs, calendar exports, email threads, and model version files.
A43: DISCLAIMER
A44: This document is a self-prepared record. It is not tax advice. Have your CPA or R&D tax counsel review QRE eligibility, base amount calculation, and credit computation before filing. WCIRB classification and CalPERS disclosures are separate matters.

Sheet Hour Breakdown
A1: CDLS · R&D HOURS BY CATEGORY & RESEARCHER · IRS § 41 Support
A3: TYPICAL R&D ACTIVITY BREAKDOWNS — Use as estimation guide for contemporaneous records
A4: R&D Activity Category | B4: Description of Typical Work | C4: QRE Eligible | D4: Typical % of Total | E4: Fed Credit Rate (§41) | F4: CA Credit Rate (§23609) | G4: Example CDLS Activities | H4: Avg Hrs Per Sprint | I4: Annual Hr Range | J4: Documentation Required
A5: AI / Software Development | B5: Building, testing, and iterating AI agent code (CESAR controller, route optimizer, onboarding agent, carbon agent) | C5: YES | D5: 35% | E5: 20% | F5: 15% | G5: CESAR agent builds; Ollama integration; Monte Carlo route algorithm; smart contract coding | H5: 40 | I5: 400–600 | J5: Git commits, code review logs, sprint tickets
A6: Financial Modeling & Analysis | B6: Iterative quantitative modeling to resolve economic uncertainty: per-truck P&L, capital stack, incentive stacking, DSCR/ROIC derivation | C6: YES | D6: 18% | E6: 20% | F6: 15% | G6: Model v1→v7.2 iterations; variable cost bottom-up build; capital stack rebuild; LP waterfall | H6: 20 | I6: 200–350 | J6: Model version files, changelog, assumption memos
A7: Regulatory & Compliance Research | B7: Technical research to determine qualification, eligibility, and impact of regulatory programs (CARB, HVIP, IRA, LCFS, SMUD) on CDLS design | C7: YES | D7: 15% | E7: 20% | F7: 15% | G7: ACF compliance mapping; HVIP deadline/stack analysis; §45W termination research; SMUD interconnection diligence | H7: 12 | I7: 120–200 | J7: Research memos, source citations, regulatory filings
A8: Testing & Validation | B8: A/B experiments, integration tests, UAT, and stress testing to resolve technical uncertainty about whether designs work as intended | C8: YES | D8: 20% | E8: 20% | F8: 15% | G8: Route optimization A/B vs human dispatcher; onboarding UAT across dealer tiers; V2G pipeline integration test | H8: 16 | I8: 180–300 | J8: Test reports, A/B results, pass/fail logs
A9: Technical Documentation | B9: Writing technical specifications, architecture docs, experiment logs, and contemporaneous R&D records (this document) | C9: YES | D9: 8% | E9: 20% | F9: 15% | G9: CESAR architecture spec; API docs; R&D log maintenance; pilot reports | H9: 8 | I9: 80–140 | J9: Document version history, date stamps
A10: Prototype & System Architecture | B10: Designing and prototyping novel system architectures where the outcome is technically uncertain | C10: YES | D10: 4% | E10: 20% | F10: 15% | G10: Three-token blockchain architecture; QIE energy arbitrage engine; multi-agent KB architecture | H10: 10 | I10: 80–120 | J10: Design docs, prototype builds, iteration logs
A11: Non-QRE: Business Development | B11: Dealer relationship management, investor pitching, CNCDA outreach — no technical uncertainty element | C11: NO | D11: — | E11: — | F11: — | G11: LP meetings, dealer demos, CNCDA events | H11: 0 | I11: — | J11: Exclude from QRE claim
A12: Non-QRE: Administrative / Legal | B12: Securities counsel engagement, LP agreement drafting, accounting, general management | C12: NO | D12: — | E12: — | F12: — | G12: Reg D counsel meetings, PPM review, tax prep | H12: 0 | I12: — | J12: Exclude from QRE claim
A14: IRS § 41 Four-Part Test: (1) Permitted purpose — develop new/improved business component (2) Technological in nature — rely on physical/biological/computer science (3) Eliminate uncertainty — uncertain capability, method, or appropriate design (4) Process of experimentation — evaluate alternatives via testing, modeling, or simulation

Sheet Summary Dashboard
A1: CALIFORNIA INVESTMENT AUTO LP · CDLS PLATFORM · R&D ACTIVITY LOG
A2: IRS § 41 Qualified Research Activities · California R&TC § 23609 · Contemporaneous Records
A4: Project Entity | B4: California Investment Auto LP (CIA) | H4: TOTAL QUALIFIED R&D HOURS (TRACKER)
A5: Platform | B5: CDLS — California Dealer Logistics Solutions | H5: ='Julio - R&D Tracker'!E68 -> 675
A6: Tax Year | B6: 2025–2026 | H6: Consolidated Contemporaneous & Reconstructed Hours (IRC § 41)
A7: Principal Investigator | B7: Julio (Managing Partner)
A8: Qualified Research Basis | B8: IRC § 41(d): Tech uncertainty, process of experimentation, technical in nature
A9: California Credit Basis | B9: R&TC § 23609 (15% of excess QREs over base amount)
A10: R&D PHASE SUMMARY · Estimated Hours by Category
A11: Phase / Milestone | B11: Start | C11: End | D11: Status | E11: AI/SW Dev (hrs) | F11: Financial Modeling (hrs) | G11: Regulatory Research (hrs) | H11: Testing & Validation (hrs) | I11: Documentation (hrs) | J11: Total Estimated Hrs | K11: Qualified Hrs (QRE %) | L11: Actual Logged Hrs | M11: Notes
A12: Phase 0: Concept & Feasibility | B12: 2024-Q1 | C12: 2024-Q2 | D12: Complete | E12: 80 | F12: 120 | G12: 60 | H12: 40 | I12: 60 | J12: =SUM(E12:I12) -> 360 | K12: =J12*0.85 -> 306 | L12: =SUMIF('Julio - R&D Tracker'!$C$6:$C$67, "*"&LEFT(A12,7)&"*", 'Julio - R&D Tracker'!$E$6:$E$67) -> 0
A13: Phase 1: CESAR Agent Architecture | B13: 2024-Q3 | C13: 2024-Q4 | D13: Complete | E13: 280 | F13: 60 | G13: 30 | H13: 80 | I13: 50 | J13: =SUM(E13:I13) -> 500 | K13: =J13*0.9 -> 450 | L13: =SUMIF('Julio - R&D Tracker'!$C$6:$C$67, "*"&LEFT(A13,7)&"*", 'Julio - R&D Tracker'!$E$6:$E$67) -> 14
A14: Phase 2: Route Optimization (MCMC) | B14: 2024-Q4 | C14: 2025-Q1 | D14: Complete | E14: 220 | F14: 40 | G14: 20 | H14: 100 | I14: 40 | J14: =SUM(E14:I14) -> 420 | K14: =J14*0.9 -> 378 | L14: =SUMIF('Julio - R&D Tracker'!$C$6:$C$67, "*"&LEFT(A14,7)&"*", 'Julio - R&D Tracker'!$E$6:$E$67) -> 52
A15: Phase 3: Financial Model v7.2 | B15: 2025-Q1 | C15: 2025-Q2 | D15: Complete | E15: 60 | F15: 340 | G15: 80 | H15: 60 | I15: 80 | J15: =SUM(E15:I15) -> 620 | K15: =J15*0.75 -> 465 | L15: =SUMIF('Julio - R&D Tracker'!$C$6:$C$67, "*"&LEFT(A15,7)&"*", 'Julio - R&D Tracker'!$E$6:$E$67) -> 70
A16: Phase 4: Blockchain / Token Design | B16: 2025-Q2 | C16: 2025-Q3 | D16: Complete | E16: 180 | F16: 80 | G16: 60 | H16: 90 | I16: 50 | J16: =SUM(E16:I16) -> 460 | K16: =J16*0.85 -> 391 | L16: =SUMIF('Julio - R&D Tracker'!$C$6:$C$67, "*"&LEFT(A16,7)&"*", 'Julio - R&D Tracker'!$E$6:$E$67) -> 54
A17: Phase 5: V2G / CAISO Integration | B17: 2025-Q3 | C17: 2025-Q4 | D17: Complete | E17: 160 | F17: 40 | G17: 80 | H17: 120 | I17: 60 | J17: =SUM(E17:I17) -> 460 | K17: =J17*0.88 -> 404.8 | L17: =SUMIF('Julio - R&D Tracker'!$C$6:$C$67, "*"&LEFT(A17,7)&"*", 'Julio - R&D Tracker'!$E$6:$E$67) -> 52
A18: Phase 6: Dealer Onboarding Agent | B18: 2025-Q4 | C18: 2026-Q1 | D18: Complete | E18: 200 | F18: 30 | G18: 40 | H18: 80 | I18: 60 | J18: =SUM(E18:I18) -> 410 | K18: =J18*0.9 -> 369 | L18: =SUMIF('Julio - R&D Tracker'!$C$6:$C$67, "*"&LEFT(A18,7)&"*", 'Julio - R&D Tracker'!$E$6:$E$67) -> 30
A19: Phase 7: Carbon Credit Agent | B19: 2026-Q1 | C19: 2026-Q2 | D19: In Progress | E19: 160 | F19: 40 | G19: 100 | H19: 80 | I19: 50 | J19: =SUM(E19:I19) -> 430 | K19: =J19*0.88 -> 378.4 | L19: =SUMIF('Julio - R&D Tracker'!$C$6:$C$67, "*"&LEFT(A19,7)&"*", 'Julio - R&D Tracker'!$E$6:$E$67) -> 28
A20: Phase 8: KB Multi-Agent System | B20: 2026-Q2 | C20: 2026-Q3 | D20: In Progress | E20: 240 | F20: 20 | G20: 20 | H20: 60 | I20: 40 | J20: =SUM(E20:I20) -> 380 | K20: =J20*0.9 -> 342 | L20: =SUMIF('Julio - R&D Tracker'!$C$6:$C$67, "*"&LEFT(A20,7)&"*", 'Julio - R&D Tracker'!$E$6:$E$67) -> 20
A21: Phase 9: Pilot Launch & Validation | B21: 2026-Q3 | C21: 2026-Q4 | D21: Planned | E21: 120 | F21: 80 | G21: 60 | H21: 200 | I21: 80 | J21: =SUM(E21:I21) -> 540 | K21: =J21*0.8 -> 432 | L21: =SUMIF('Julio - R&D Tracker'!$C$6:$C$67, "*"&LEFT(A21,7)&"*", 'Julio - R&D Tracker'!$E$6:$E$67) -> 0
A22: TOTALS | E22: =SUM(E12:E21) -> 1700 | F22: =SUM(F12:F21) -> 850 | G22: =SUM(G12:G21) -> 550 | H22: =SUM(H12:H21) -> 910 | I22: =SUM(I12:I21) -> 570 | J22: =SUM(J12:J21) -> 4580 | K22: =SUM(K12:K21) -> 3916.2 | L22: =SUM(L12:L21) -> 320
A24: LEGEND
A25: Blue text = Hardcoded input (edit these)
A26: Green = Qualified Research Expense hours
A27: Gold = In Progress milestones
A28: Dark = Section headers / totals
